Workbook

Sheet README
A1: FSAE DRIVERLESS — PURCHASING PLAN BY ROLE
A4: What this is | B4: Every item that needs to be bought to stand up the driverless program, assigned to the role on your org chart that owns it. Built from the research report (rules, sensors, compute, software, simulation, mechanical retrofit, testing, KPIs, budget tiers).
A5: How to use it | B5: 1) Open 'Master BOM' — it is the single source of truth. 2) Overwrite the blue 'Unit Cost' cells with real quotes as they come in. 3) Every role sheet and the dashboard update automatically. 4) Work the 'Order First' sheet before anything else.
A6: Tier logic | B6: T1 / T2 / T3 flags mark which items you buy at each funding level. They are ALTERNATIVE configurations, not cumulative — e.g. the LiDAR line appears three times (Livox Mid-360 / Ouster OS1-32 / OS1-128) with only one flagged per tier. Set a flag to 1 or 0 to re-scope a tier and every total follows.
A7: Currency | B7: All figures are USD. The dashboard converts to CAD using an editable FX rate plus a duty/brokerage uplift — budget roughly 15-25% on top of USD list for a Canadian team.
A8: Why totals exceed the report | B8: The research report's headline tiers (~$12k / $41k / $91k) covered hardware and software only. This workbook adds the things that actually appear on a purchase order and get forgotten: competition entry, test-site agreements and insurance, indoor winter space, the electronics bench, connectors and crimp tooling, PCB spins, spares and test-day kit. Expect roughly $27k / $68k / $120k as a result. That gap IS the finding — the sensors were never the expensive part.
A10: LEGEND
A11: Blue text | B11: Hardcoded input you are expected to overwrite (unit costs, FX rate, uplift %).
A12: Black text | B12: Formula-driven — do not overwrite.
A13: Green text | B13: Pulled from another sheet.
A14: Yellow fill | B14: Key assumption to review.
A15: Orange fill | B15: Ownership gap — see below.
A16: Red 'Critical' | B16: Rules-blocking or schedule-blocking. You cannot pass technical inspection without it.
A18: GAPS AND FLAGS FROM YOUR ORG CHART
A19: 1. No mechanical/actuation owner | B19: The steering actuator and the Emergency Brake System are the two hardest, most rules-critical purchases on this list (roughly $2,100 shoestring to $10,000 well-funded), and no box on your chart owns them. Firmware's note says 'more mechanical and electrical interfacing work' and DSO owns 'integration between subsystems (including mech and sparkies)' — but neither is an owner. These items are parked under 'Mech/EE Interface — UNASSIGNED' until you name someone. This is the single biggest org risk on the chart, because these are also the items most likely to fail scrutineering.
A20: 2. Testing owns the RC platform | B20: The F1TENTH build sits under Evan because Testing owns development methodology, but Perception, Mapping and Planning all depend on it daily. Treat it as shared infrastructure with Evan as custodian.
A21: 3. Sim owns storage, Firmware owns onboard logging | B21: Ethan's 'storage architecture' responsibility covers the NAS and offload workflow; the on-car NVMe sits with Mason because it is part of compute bring-up. Make sure they agree on the handoff at the end of each test day.
A22: 4. Two workstations, two owners | B22: Perception owns the ML training box; Sim owns the simulation/visualisation box. At Tier 1 both are $0 because you reuse lab machines. Do not double-buy.
A23: 5. Planning has almost no hardware | B23: That is correct and expected — Ced's spend is TTC tire data and solver licences. His dependency is on other people's actuator interfaces landing on time, not on procurement.
A25: SHEET GUIDE
A26: Master BOM | B26: Every line item. Filterable by role, category, tier, priority.
A27: Budget Dashboard | B27: Totals by role and by category for each tier, plus CAD conversion.
A28: Role sheets | B28: One per box on the org chart — hand each person their own tab.
A29: Order First | B29: Critical-path items sorted by lead time. Start here.
A30: Sponsorship Targets | B30: What to ask for, from whom, and who owns the ask.
A32: SOURCE | B32: Derived from the research report 'Formula Student Driverless from Scratch: Equipment, Software, and Infrastructure Playbook for a Winnipeg EV-to-DV Retrofit'. Rules references are to the FSAE Driverless Supplement 2026 and the FSG Formula Student Rules 2026 / Driverless Specification 2026 — reverify every figure against the rulebook for the year you actually enter.

Sheet BOM Master
A1: FSAE DRIVERLESS - MASTER BOM
A2: Complete bill of materials and resources to stand up the driverless program. All figures USD engineered estimates - verify with live quotes.
A4: ID | B4: Category | C4: Item / Purpose | D4: Recommended Model / Spec | E4: Qty | F4: Unit Cost (USD) | G4: Ext. Cost (USD) | H4: Priority | I4: Lead Time | J4: Sponsorable? | K4: Notes / Rationale
A5: DV-001 | B5: Safety / Rules Hardware | C5: Remote Emergency System (RES) - European events | D5: Gross-Funk GF2000i-codec + T53R98, 2022 hw rev with E-Key | E5: 1 | F5: 2000 | G5: =E5*F5 | H5: Critical | I5: 6-10 weeks | J5: Possible (Ferchau sponsored Racetech's) | K5: ORDER FIRST - longest lead item. Contact christian.keller@grossfunk.de / fsg.one/res. SIL3, CANopen Node-ID 0x011, 430-440 MHz.
A6: DV-002 | B6: Safety / Rules Hardware | C6: Remote Stop System - FSAE North America | D6: FSAE Remote Stop: Vehicle Module + Control Box + Remote Stop Relay | E6: 1 | F6: 500 | G6: =E6*F6 | H6: Critical | I6: 4-8 weeks | J6: No | K6: NA uses its own standard, NOT the Gross-Funk unit. Design the shutdown circuit so either RES drops in.
A7: DV-003 | B7: Safety / Rules Hardware | C7: ASSI / DSSI status indicator lights | D7: 3x amber+blue LED panels, black background, >=15 cm2 shining area, LEDs <=20mm apart | E7: 3 | F7: 85 | G7: =E7*F7 | H7: Critical | I7: 2-3 weeks | J7: No | K7: States: Off=off, Ready=yellow steady, Driving=yellow flashing, Finished=blue steady, Emergency=blue flashing. Both sides behind cockpit + rear centreline.
A8: DV-004 | B8: Safety / Rules Hardware | C8: Driverless alert sound device | D8: Automotive buzzer, 80-90 dBA, 1-5 Hz at 50% duty, 8-10 s | E8: 1 | F8: 60 | G8: =E8*F8 | H8: Critical | I8: 1-2 weeks | J8: No | K8: Sounds on Emergency state. Verify dBA at the rules-specified measurement distance.
A9: DV-005 | B9: Safety / Rules Hardware | C9: Autonomous Mission Indicator (AMI) display | D9: Small dash display / LED set showing selected mission | E9: 1 | F9: 80 | G9: =E9*F9 | H9: Critical | I9: 1-2 weeks | J9: No | K9: Missions: acceleration, skidpad, trackdrive, braketest, inspection, autocross. Mount near dash/ASMS.
A10: DV-006 | B10: Safety / Rules Hardware | C10: ASMS / DSMS master switch | D10: Direct-acting rotary switch, blue circular area >=50mm, labelled 'DS', lockout/tagout capable | E10: 1 | F10: 120 | G10: =E10*F10 | H10: Critical | I10: 2 weeks | J10: No | K10: Must be direct-acting (not via relay/logic). When OFF the car must remain normally drivable and pushable.
A11: DV-007 | B11: Safety / Rules Hardware | C11: DV shutdown-circuit relay set | D11: Driverless System Relay (NO permissive) + Remote Stop Relay + NC bypass relay + EBS Relay (fail-open) | E11: 1 | F11: 300 | G11: =E11*F11 | H11: Critical | I11: 2-3 weeks | J11: No | K11: Automotive-rated relays; document the schematic for scrutineering.
A12: DV-008 | B12: Safety / Rules Hardware | C12: DV livery, signage and required markings | D12: Vinyl decals, 'Brake Release' labels, DV class markings | E12: 1 | F12: 150 | G12: =E12*F12 | H12: High | I12: 1-2 weeks | J12: Likely (local print shop) | K12: Check the current-year rulebook for exact wording and placement.
A13: DV-009 | B13: Software / License | C13: Rulebook + standards library | D13: ISO 26262 and ISO 21448 (SOTIF) - purchase or university library access | E13: 1 | F13: 0 | G13: =E13*F13 | H13: High | I13: 1 week | J13: n/a | K13: ISO copies are expensive (~US$200-2,000/part). CHECK THE UNIVERSITY LIBRARY FIRST - usually free access.
A14: DV-010 | B14: Facilities / Admin | C14: Competition registration + DV class entry | D14: FSAE Electric (Driverless Class) and/or FSG entry fees | E14: 1 | F14: 1500 | G14: =E14*F14 | H14: Critical | I14: Registration window | J14: Sponsor-funded | K14: Placeholder - confirm current-year fees. Registration windows are strict and early.
A15: DV-011 | B15: Software / License | C15: Git hosting + CI minutes | D15: GitHub Education (free private repos + Actions) or self-hosted GitLab | E15: 1 | F15: 0 | G15: =E15*F15 | H15: Critical | I15: Immediate | J15: Free for students | K15: Apply via GitHub Education. Zero cost - decide the version-control strategy in month 1.
A16: DV-012 | B16: Software / License | C16: Project management + documentation tooling | D16: Notion/Linear/Jira student tier, or self-hosted | E16: 1 | F16: 0 | G16: =E16*F16 | H16: Medium | I16: Immediate | J16: Free education tiers | K16: Free education plans exist for all three.
... A85: DV-081 | B85: Web / Comms | C85: Design assets | D85: Icon/font licences, sponsor-facing brand assets | E85: 1 | F85: 100 | G85: =E85*F85 | H85: Low | I85: 1 week | J85: Possible | K85: A credible public site materially helps sponsorship conversations.
C86: TOTAL | G86: =SUM(G5:G85)

Sheet Master BOM
A1: MASTER BOM — FSAE Driverless Program Stand-Up
A2: Single source of truth. Every other sheet references these rows. Tier flags: 1 = buy this item at that funding tier, 0 = do not. Costs are engineered estimates in USD from the research report — verify with a live quote before ordering.
A3: ID | B3: Role Owner (per org chart) | C3: Category | D3: Item / Purpose | E3: Recommended Model / Spec | F3: Qty | G3: Unit Cost (USD) | H3: Ext. Cost (USD) | I3: T1? | J3: T2? | K3: T3? | L3: Tier 1 ($) | M3: Tier 2 ($) | N3: Tier 3 ($) | O3: Priority | P3: Lead Time | Q3: Sponsorable? | R3: Rules Ref | S3: Notes / Rationale
A4: DV-001 | B4: DSO — Caleb | C4: Safety / Rules Hardware | D4: Remote Emergency System (RES) — European events | E4: Gross-Funk GF2000i-codec + T53R98, 2022 hw rev with E-Key | F4: 1 | G4: 2000 | H4: =F4*G4 | I4: 1 | J4: 1 | K4: 1 | L4: =$H4*I4 | M4: =$H4*J4 | N4: =$H4*K4 | O4: Critical | P4: 6-10 weeks | Q4: Possible (Ferchau sponsored Racetech's) | R4: FSG DS 3.1 | S4: ORDER FIRST — longest lead item. Contact christian.keller@grossfunk.de / fsg.one/res. SIL3, CANopen Node-ID 0x011, 430-440 MHz.
A5: DV-002 | B5: DSO — Caleb | C5: Safety / Rules Hardware | D5: Remote Stop System — FSAE North America | E5: FSAE Remote Stop: Vehicle Module + Control Box + Remote Stop Relay | F5: 1 | G5: 500 | H5: =F5*G5 | I5: 1 | J5: 1 | K5: 1 | L5: =$H5*I5 | M5: =$H5*J5 | N5: =$H5*K5 | O5: Critical | P5: 4-8 weeks | Q5: No | R5: FSAE DV Supplement | S5: NA uses its own standard, NOT the Gross-Funk unit. Design the shutdown circuit so either RES drops in.
A6: DV-003 | B6: DSO — Caleb | C6: Safety / Rules Hardware | D6: ASSI / DSSI status indicator lights | E6: 3x amber+blue LED panels, black background, >=15 cm2 shining area, LEDs <=20mm apart | F6: 3 | G6: 85 | H6: =F6*G6 | I6: 1 | J6: 1 | K6: 1 | L6: =$H6*I6 | M6: =$H6*J6 | N6: =$H6*K6 | O6: Critical | P6: 2-3 weeks | Q6: No | R6: FSAE DV; FSG DS | S6: States: Off=off, Ready=yellow steady, Driving=yellow flashing, Finished=blue steady, Emergency=blue flashing. Both sides behind cockpit + rear centreline.
A7: DV-004 | B7: DSO — Caleb | C7: Safety / Rules Hardware | D7: Driverless alert sound device | E7: Automotive buzzer, 80-90 dBA, 1-5 Hz at 50% duty, 8-10 s | F7: 1 | G7: 60 | H7: =F7*G7 | I7: 1 | J7: 1 | K7: 1 | L7: =$H7*I7 | M7: =$H7*J7 | N7: =$H7*K7 | O7: Critical | P7: 1-2 weeks | Q7: No | R7: FSAE DV; FSG DS | S7: Sounds on Emergency state. Verify dBA at the rules-specified measurement distance.
A8: DV-005 | B8: DSO — Caleb | C8: Safety / Rules Hardware | D8: Autonomous Mission Indicator (AMI) display | E8: Small dash display / LED set showing selected mission | F8: 1 | G8: 80 | H8: =F8*G8 | I8: 1 | J8: 1 | K8: 1 | O8: Critical | P8: 1-2 weeks | Q8: No | R8: FSAE DV; FSG DS | S8: Missions: acceleration, skidpad, trackdrive, braketest, inspection, autocross. Mount near dash/ASMS.
A9: DV-006 | B9: DSO — Caleb | C9: Safety / Rules Hardware | D9: ASMS / DSMS master switch | E9: Direct-acting rotary switch, blue circular area >=50mm, labelled 'DS', lockout/tagout capable | F9: 1 | G9: 120 | H9: =F9*G9 | I9: 1 | J9: 1 | K9: 1 | L9: ADDED TO STICKER COST | O9: Critical | P9: 2 weeks | Q9: No | R9: FSAE DV; FSG DS | S9: Must be direct-acting (not via relay/logic). When OFF the car must remain normally drivable and pushable.
A10: DV-007 | B10: DSO — Caleb | C10: Safety / Rules Hardware | D10: DV shutdown-circuit relay set | E10: Driverless System Relay (NO permissive) + Remote Stop Relay + NC bypass relay + EBS Relay (fail-open) | F10: 1 | G10: 300 | H10: =F10*G10 | I10: 1 | J10: 1 | K10: 1 | L10: =$H10*I10 | M10: =$H10*J10 | N10: =$H10*K10 | O10: Critical | P10: 2-3 weeks | Q10: No | R10: FSAE DV; FSG DS | S10: Automotive-rated relays; document the schematic for scrutineering.
A11: DV-008 | B11: DSO — Caleb | C11: Safety / Rules Hardware | D11: DV livery, signage and required markings | E11: Vinyl decals, 'Brake Release' labels, DV class markings | F11: 1 | G11: 150 | H11: =F11*G11 | I11: 1 | J11: 1 | K11: 1 | L11: ADDED TO STICKER COST | O11: High | P11: 1-2 weeks | Q11: Likely (local print shop) | R11: FSAE DV; FSG DS | S11: Check the current-year rulebook for exact wording and placement.
A12: DV-009 | B12: DSO — Caleb | C12: Software / License | D12: Rulebook + standards library | E12: ISO 26262 and ISO 21448 (SOTIF) - purchase or university library access | F12: 1 | G12: 0 | H12: =F12*G12 | I12: 1 | J12: 1 | K12: 1 | L12: =$H12*I12 | M12: =$H12*J12 | N12: =$H12*K12 | O12: High | P12: 1 week | Q12: n/a | R12: Design event | S12: ISO copies are expensive (~US$200-2,000/part). CHECK THE UNIVERSITY LIBRARY FIRST — usually free access.
A13: DV-010 | B13: DSO — Caleb | C13: Facilities / Admin | D13: Competition registration + DV class entry | E13: FSAE Electric (Driverless Class) and/or FSG entry fees | F13: 1 | G13: 1500 | H13: =F13*G13 | I13: 1 | J13: 1 | K13: 1 | O13: Critical | P13: Registration window | Q13: Sponsor-funded | R13: Event handbook | S13: Placeholder — confirm current-year fees. Registration windows are strict and early.
A14: DV-011 | B14: Team-Wide — Everyone | C14: Software / License | D14: Git hosting + CI minutes | E14: GitHub Education (free private repos + Actions) or self-hosted GitLab | F14: 1 | G14: 0 | H14: =F14*G14 | I14: 1 | J14: 1 | K14: 1 | L14: =$H14*I14 | M14: =$H14*J14 | N14: =$H14*K14 | O14: Critical | P14: Immediate | Q14: Free for students | R14: n/a | S14: Apply via GitHub Education. Zero cost — decide the version-control strategy in month 1.
A15: DV-012 | B15: Team-Wide — Everyone | C15: Software / License | D15: Project management + documentation tooling | E15: Notion/Linear/Jira student tier, or self-hosted | F15: 1 | G15: 0 | H15: =F15*G15 | I15: 1 | J15: 1 | K15: 1 | L15: =$H15*I15 | M15: =$H15*J15 | N15: =$H15*K15 | O15: Medium | P15: Immediate | Q15: Free education tiers | R15: n/a | S15: Free education plans exist for all three.
A16: DV-013 | B16: Team-Wide — Everyone | C16: Software / License | D16: MATLAB / Simulink + toolboxes | E16: Vehicle Dynamics Blockset, MPC Toolbox, Automated Driving Toolbox | F16: 1 | G16: 0 | H16: =F16*G16 | I16: 1 | J16: 1 | K16: 1 | L16: =$H16*I16 | M16: =$H16*J16 | N16: =$H16*K16 | O16: High | P16: 2-4 weeks | Q16: Yes — MathWorks sponsors FS teams | R16: n/a | S16: MathWorks gives free competition licences to Formula Student teams. Apply early; also check your campus site licence.
A17: DV-014 | B17: Team-Wide — Everyone | C17: Software / License | D17: CAD / PDM (already sponsored) | E17: SOLIDWORKS / 3DEXPERIENCE via SAE Collegiate Design Series | F17: 1 | G17: 0 | H17: =F17*G17 | I17: 1 | J17: 1 | K17: 1 | L17: =$H17*I17 | M17: =$H17*J17 | N17: =$H17*K17 | O17: Medium | P17: Already held | Q17: Yes — Dassault via SAE | R17: n/a | S17: Apply under a TEAM email, not a personal one. Export data at end of season.
A18: DV-015 | B18: Perception — Amanuel + Irvine + Caleb | C18: Sensing — LiDAR | D18: Primary LiDAR (Tier 1 pick) | E18: Livox Mid-360 — 360x59 deg, 40m @10% / 70m @80%, 265g, IP67, built-in IMU, 0.1m blind zone | F18: 1 | G18: 749 | H18: =F18*G18 | I18: 1 | J18: 0 | K18: 0 | M18: =$H18*J18 | N18: =$H18*K18 | O18: Critical | P18: 3-6 weeks | Q18: Possible via distributor | R18: n/a | S18: Best price/performance for a new team. Non-repetitive scan needs point accumulation. Weak vendor support.
A19: DV-016 | B19: Perception — Amanuel + Irvine + Caleb | C19: Sensing — LiDAR | D19: Primary LiDAR (Tier 2 pick) | E19: Ouster OS1-32 Rev7 — 32ch, 45 deg vertical FOV, 90m @10%, IP68/69K | F19: 1 | G19: 6000 | H19: =F19*G19 | I19: 0 | J19: 1 | K19: 0 | L19: =$H19*I19 | M19: =$H19*J19 | N19: =$H19*K19 | O19: Critical | P19: 6-12 weeks | Q19: Yes — approach Ouster | R19: n/a | S19: ~US$8k list, ~US$6k non-profit pricing. Used OS1-32 / VLP-16 seen at US$1.5-5k — viable fallback.
A20: DV-017 | B20: Perception — Amanuel + Irvine + Caleb | C20: Sensing — LiDAR | D20: Primary LiDAR (Tier 3 pick) | E20: Ouster OS1-128 — dense 128ch for long-range cone detection | F20: 1 | G20: 12000 | H20: =F20*G20 | I20: 0 | J20: 0 | K20: 1 | L20: =$H20*I20 | M20: =$H20*J20 | N20: =$H20*K20 | O20: Critical | P20: 8-14 weeks | Q20: Yes — approach Ouster | R20: n/a | S20: Perception range gates car speed. 128ch buys detection distance, which buys lap time.
A21: DV-018 | B21: Perception — Amanuel + Irvine + Caleb | C21: Sensing — LiDAR | D21: Secondary near-field LiDAR | E21: Livox Mid-360 as near-field/blind-spot fill alongside the OS1-128 | F21: 1 | G21: 749 | H21: =F21*G21 | I21: 0 | J21: 0 | K21: 1 | L21: =$H21*I21 | M21: =$H21*J21 | N21: =$H21*K21 | O21: Medium | P21: 3-6 weeks | Q21: Possible | R21: n/a | S21: Covers the OS1's near blind zone in tight hairpins (~9m diameter).
A22: DV-019 | B22: Perception — Amanuel + Irvine + Caleb | C22: Sensing — Camera | D22: Stereo camera (Tier 1 pick) | E22: Used Stereolabs ZED 2i (rolling shutter, IP66, built-in IMU) or RealSense D455 | F22: 1 | G22: 350 | H22: =F22*G22 | I22: 1 | J22: 0 | K22: 0 | M22: =$H22*J22 | N22: =$H22*K22 | O22: Critical | P22: 1-3 weeks | Q22: Yes — Stereolabs has a student programme | R22: n/a | S22: Rolling shutter smears at speed — acceptable at the <5 m/s year-1 target. Verify RealSense availability; that line has had discontinuation uncertainty.
A23: DV-020 | B23: Perception — Amanuel + Irvine + Caleb | C23: Sensing — Camera | D23: Global-shutter cameras (Tier 2 pick) | E23: 2x Stereolabs ZED X (GMSL2, global shutter, 1200p/60, IP67) + ZED Box/capture card | F23: 1 | G23: 2000 | H23: =F23*G23 | I23: 0 | J23: 1 | K23: 0 | L23: =$H23*I23 | M23: =$H23*J23 | N23: =$H23*K23 | O23: Critical | P23: 4-8 weeks | Q23: Yes — Stereolabs | R23: n/a | S23: Global shutter is strongly preferred on a car pulling >1g. GMSL2 tolerates long runs near the tractive system.
A24: DV-021 | B24: Perception — Amanuel + Irvine + Caleb | C24: Sensing — Camera | D24: Multi-camera array (Tier 3 pick) | E24: 3x ZED X / Basler ace global-shutter + GMSL2 infrastructure | F24: 1 | G24: 4000 | H24: =F24*G24 | I24: 0 | J24: 0 | K24: 1 | L24: =$H24*I24 | M24: =$H24*J24 | N24: =$H24*K24 | O24: Critical | P24: 6-10 weeks | Q24: Yes — Stereolabs / Basler | R24: n/a | S24: Near-wide (~120 deg) + far-narrow (~50-60 deg) pair, as used by AMZ and Elefant. Hardware-sync the array.
A25: DV-022 | B25: Perception — Amanuel + Irvine + Caleb | C25: Sensing — Camera | D25: Lens set for machine-vision cameras | E25: C-mount lenses sized for cone detection at 25m (far ~50-60 deg HFOV, near ~120 deg) | F25: 2 | G25: 300 | H25: =F25*G25 | I25: 0 | J25: 0 | K25: 1 | L25: =$H25*I25 | M25: =$H25*J25 | N25: =$H25*K25 | O25: High | P25: 3-5 weeks | Q25: Possible | R25: n/a | S25: A 325mm cone at 25m on 1080p/50 deg HFOV is only ~15px tall — near the detection floor. Do the FOV maths before ordering.
A26: DV-023 | B26: Perception — Amanuel + Irvine + Caleb | C26: Test Equipment | D26: Calibration targets | E26: Rigid checkerboard board + printed AprilTag boards + calibration jig | F26: 1 | G26: 200 | H26: =F26*G26 | I26: 1 | J26: 1 | K26: 1 | L26: =$H26*I26 | M26: =$H26*J26 | N26: =$H26*K26 | O26: High | P26: 2 weeks | Q26: No | R26: n/a | S26: Use with Kalibr (camera-IMU), lidar_camera_calibration, direct_visual_lidar_calibration. Rigidity matters more than size.
A27: DV-024 | B27: Perception — Amanuel + Irvine + Caleb | C27: Actuation / Mounting | D27: Sensor mounts + vibration isolation | E27: Machined/printed LiDAR nosecone mount, main-hoop camera mounts, wire-rope isolators, Sorbothane | F27: 1 | G27: 600 | H27: =F27*G27 | I27: 1 | J27: 0 | K27: 0 | L27: =$H27*I27 | M27: =$H27*J27 | N27: =$H27*K27 | O27: High | P27: 3-4 weeks | Q27: Possible (machining sponsor) | R27: FSAE DT.2.3 | S27: Tier 1 = basic mounts. Nose mount gives the best forward view but is crash-exposed; protect it or use replaceable side boxes.
A28: DV-025 | B28: Perception — Amanuel + Irvine + Caleb | C28: Actuation / Mounting | D28: Engineered sensor mounts + IP enclosures | E28: CNC mounts, isolators, IP-rated camera/LiDAR housings | F28: 1 | G28: 1900 | H28: =F28*G28 | I28: 0 | J28: 1 | K28: 1 | L28: =$H28*I28 | M28: =$H28*J28 | N28: =$H28*K28 | O28: High | P28: 4-6 weeks | Q28: Possible (machining sponsor) | R28: FSAE DT.2.3 | S28: AS components must sit inside the primary-structure/tire envelope or allowed aero zones — check DT.2.3 before designing.
A29: DV-026 | B29: Perception — Amanuel + Irvine + Caleb | C29: Compute | D29: ML training workstation | E29: Ryzen 9 / i9, 64GB RAM, RTX 4080 (16-24GB), 2TB NVMe | F29: 1 | G29: 3500 | H29: =F29*G29 | I29: 0 | J29: 1 | K29: 0 | L29: =$H29*I29 | N29: =$H29*K29 | O29: High | P29: 2-4 weeks | Q29: Yes — NVIDIA academic seeding | R29: n/a | S29: Tier 1: use existing lab machines or campus HPC (cost $0). Needed to train YOLO/segmentation on FSOCO.
A30: DV-027 | B30: Perception — Amanuel + Irvine + Caleb | C30: Compute | D30: ML training workstations (x2) | E30: Dual RTX 4090 workstations for parallel training + campus HPC time | F30: 2 | G30: 4000 | H30: =F30*G30 | I30: 0 | J30: 0 | K30: 1 | L30: =$H30*I30 | O30: High | P30: 3-5 weeks | Q30: Yes — NVIDIA academic seeding | R30: n/a | S30: Only worth it once you have a real labelling and retraining cadence.
A31: DV-028 | B31: Perception — Amanuel + Irvine + Caleb | C31: Software / License | D31: Cone dataset | E31: FSOCO — 44,195 images / 316,669 labelled cones, bboxes + instance segmentation | F31: 1 | G31: 0 | H31: =F31*G31 | I31: 1 | J31: 1 | K31: 1 | L31: =$H31*I31 | M31: =$H31*J31 | N31: =$H31*K31 | O31: Critical | P31: Immediate | Q31: Free | R31: n/a | S31: PUBLIC since Aug 2022 — the old contribution buy-in is gone. fsoco-dataset.com. Contributing back is still encouraged.
A32: DV-029 | B32: Perception — Amanuel + Irvine + Caleb | C32: Software / License | D32: Detection model licence check | E32: YOLOX / MMDetection / Detectron2 (permissive) vs Ultralytics YOLO (AGPL-3.0) | F32: 1 | G32: 0 | H32: =F32*G32 | I32: 1 | J32: 1 | K32: 1 | L32: =$H32*I32 | M32: =$H32*J32 | N32: =$H32*K32 | O32: High | P32: Immediate | Q32: Free | R32: n/a | S32: Ultralytics is AGPL-3.0 — can force open-sourcing of dependent code if distributed. Fine for competition, a problem if a sponsor wants closed code.
A33: DV-030 | B33: Mapping — Angel | C33: Sensing — GNSS/INS | D33: GNSS/INS (Tier 1 pick) | E33: ArduSimple simpleRTK2B (u-blox ZED-F9P) + antenna, paired with a separate IMU | F33: 1 | G33: 400 | H33: =F33*G33 | I33: 1 | J33: 0 | K33: 0 | L33: SPONSORED (1K) | N33: =$H33*K33 | O33: High | P33: 2-4 weeks | Q33: No | R33: n/a | S33: Budget RTK. No dual-antenna heading — yaw at standstill will be weak, which hurts skidpad starts.
A34: DV-031 | B34: Mapping — Angel | C34: Sensing — GNSS/INS | D34: GNSS/INS (Tier 2 pick) | E34: SBG Ellipse-D — dual-antenna heading, L1/L2 quad-constellation RTK (or VectorNav VN-300) | F34: 1 | G34: 5000 | H34: =F34*G34 | I34: 0 | J34: 1 | K34: 0 | L34: =$H34*I34 | M34: =$H34*J34 | N34: =$H34*K34 | O34: Critical | P34: 6-10 weeks | Q34: YES — SBG and VectorNav both run student programmes | R34: n/a | S34: Highest-value sponsorship ask on the whole BOM. Zurich UAS reported driverless was 'impossible' from position drift until they added an Ellipse-D. SBG is ITAR-free.
A35: DV-032 | B35: Mapping — Angel | C35: Sensing — GNSS/INS | D35: GNSS/INS + own RTK base (Tier 3 pick) | E35: SBG Ellipse-D + dedicated RTK base station | F35: 1 | G35: 8000 | H35: =F35*G35 | I35: 0 | J35: 0 | K35: 1 | L35: SPONSORED (8K) | O35: Critical | P35: 8-12 weeks | Q35: YES — SBG | R35: n/a | S35: Own base removes reliance on cellular NTRIP at remote Prairie test sites.
A36: DV-033 | B36: Mapping — Angel | C36: Sensing — GNSS/INS | D36: Dual GNSS antennas + low-loss cabling | E36: L1/L2 survey antennas x2 + LMR cabling, roll-hoop/bodywork mounts | F36: 1 | G36: 400 | H36: =F36*G36 | I36: 0 | J36: 1 | K36: 1 | L36: =$H36*I36 | M36: =$H36*J36 | N36: =$H36*K36 | O36: High | P36: 3-4 weeks | Q36: Bundled with INS sponsorship | R36: n/a | S36: Antenna baseline length drives heading accuracy — plan the mounting geometry with the mech team.
A37: DV-034 | B37: Mapping — Angel | C37: Software / License | D37: RTK correction service (Canada) | E37: Commercial NTRIP subscription (RTKdata / RTK FIX) — annual | F37: 1 | G37: 600 | H37: =F37*G37 | I37: 0 | J37: 1 | K37: 1 | L37: =$H37*I37 | M37: =$H37*J37 | N37: =$H37*K37 | O37: Medium | P37: 1 week | Q37: Possible | R37: n/a | S37: Tier 1: free casters RTK2go / Emlid Caster ($0). Only Quebec offers free provincial corrections — a Manitoba team will run its own base or pay. Cross-check NRCan's RTK network list.
A38: DV-035 | B38: Mapping — Angel | C38: Sensing — GNSS/INS | D38: RTK base station (budget) | E38: ArduSimple or Emlid Reach base + tripod, for own corrections | F38: 1 | G38: 600 | H38: =F38*G38 | I38: 0 | J38: 1 | K38: 0 | L38: =$H38*I38 | M38: =$H38*J38 | N38: =$H38*K38 | O38: Medium | P38: 3-4 weeks | Q38: No | R38: n/a | S38: RTK holds to ~30-50 km from base. Cheaper than a multi-year correction subscription.
A39: DV-036 | B39: Mapping — Angel | C39: Test Equipment | D39: Optical ground-speed sensor (ground truth) | E39: Kistler Correvit (or GeneSys ADMA) — slip-free velocity reference | F39: 1 | G39: 6000 | H39: =F39*G39 | I39: 0 | J39: 0 | K39: 1 | L39: SPONSORED? | M39: =$H39*J39 | N39: =$H39*K39 | O39: Low | P39: 10-16 weeks | Q39: Yes — usually sponsored | R39: n/a | S39: Validation only, shared with Testing. AMZ and Elefant both ran ground-speed sensors. Skip unless sponsored.
A40: DV-037 | B40: Mapping — Angel | C40: Test Equipment | D40: Survey-grade RTK rover for map ground truth | E40: Handheld RTK rover to survey true cone positions on the test track | F40: 1 | G40: 600 | H40: =F40*G40 | I40: 0 | J40: 1 | K40: 1 | L40: =$H40*I40 | M40: =$H40*J40 | N40: =$H40*K40 | O40: High | P40: 3-4 weeks | Q40: No | R40: n/a | S40: You cannot report a mapping RMSE without surveyed cone truth. Target <1m year 1; AMZ achieved 0.29m.
...

Sheet Budget Dashboard
A1: BUDGET DASHBOARD
A2: All figures roll up live from 'Master BOM'. Change any unit cost or tier flag there and this updates.
A4: ASSUMPTIONS
A5: USD to CAD exchange rate | B5: 1.37 | C5: Editable — set to today's rate.
A6: Duty, brokerage and shipping uplift | B6: 0.12 | C6: Canadian import uplift on top of USD list. Report guidance: budget 15-25% total including FX movement.
A8: SPEND BY ROLE (USD)
A9: Role (per org chart) | B9: Tier 1 — Shoestring | C9: Tier 2 — Moderate | D9: Tier 3 — Well-funded | E9: Line items
A10: DSO — Caleb | B10: =SUMIFS('Master BOM'!$L$4:$L$114,'Master BOM'!$B$4:$B$114,$A10) | C10: =SUMIFS('Master BOM'!$M$4:$M$114,'Master BOM'!$B$4:$B$114,$A10) | D10: =SUMIFS('Master BOM'!$N$4:$N$114,'Master BOM'!$B$4:$B$114,$A10) | E10: =COUNTIFS('Master BOM'!$B$4:$B$114,$A10)
A11: Team-Wide — Everyone | B11: =SUMIFS('Master BOM'!$L$4:$L$114,'Master BOM'!$B$4:$B$114,$A11) | C11: =SUMIFS('Master BOM'!$M$4:$M$114,'Master BOM'!$B$4:$B$114,$A11) | D11: =SUMIFS('Master BOM'!$N$4:$N$114,'Master BOM'!$B$4:$B$114,$A11) | E11: =COUNTIFS('Master BOM'!$B$4:$B$114,$A11)
A12: Perception — Amanuel + Irvine + Caleb | B12: =SUMIFS('Master BOM'!$L$4:$L$114,'Master BOM'!$B$4:$B$114,$A12) | C12: =SUMIFS('Master BOM'!$M$4:$M$114,'Master BOM'!$B$4:$B$114,$A12) | D12: =SUMIFS('Master BOM'!$N$4:$N$114,'Master BOM'!$B$4:$B$114,$A12) | E12: =COUNTIFS('Master BOM'!$B$4:$B$114,$A12)
A13: Mapping — Angel | B13: =SUMIFS('Master BOM'!$L$4:$L$114,'Master BOM'!$B$4:$B$114,$A13) | C13: =SUMIFS('Master BOM'!$M$4:$M$114,'Master BOM'!$B$4:$B$114,$A13) | D13: =SUMIFS('Master BOM'!$N$4:$N$114,'Master BOM'!$B$4:$B$114,$A13) | E13: =COUNTIFS('Master BOM'!$B$4:$B$114,$A13)
A14: Planning — Ced | B14: =SUMIFS('Master BOM'!$L$4:$L$114,'Master BOM'!$B$4:$B$114,$A14) | C14: =SUMIFS('Master BOM'!$M$4:$M$114,'Master BOM'!$B$4:$B$114,$A14) | D14: =SUMIFS('Master BOM'!$N$4:$N$114,'Master BOM'!$B$4:$B$114,$A14) | E14: =COUNTIFS('Master BOM'!$B$4:$B$114,$A14)
A15: Firmware — Mason | B15: =SUMIFS('Master BOM'!$L$4:$L$114,'Master BOM'!$B$4:$B$114,$A15) | C15: =SUMIFS('Master BOM'!$M$4:$M$114,'Master BOM'!$B$4:$B$114,$A15) | D15: =SUMIFS('Master BOM'!$N$4:$N$114,'Master BOM'!$B$4:$B$114,$A15) | E15: =COUNTIFS('Master BOM'!$B$4:$B$114,$A15)
A16: Mech/EE Interface — UNASSIGNED (DSO coordinates) | B16: =SUMIFS('Master BOM'!$L$4:$L$114,'Master BOM'!$B$4:$B$114,$A16) | C16: =SUMIFS('Master BOM'!$M$4:$M$114,'Master BOM'!$B$4:$B$114,$A16) | D16: =SUMIFS('Master BOM'!$N$4:$N$114,'Master BOM'!$B$4:$B$114,$A16) | E16: =COUNTIFS('Master BOM'!$B$4:$B$114,$A16)
A17: Testing — Evan | B17: =SUMIFS('Master BOM'!$L$4:$L$114,'Master BOM'!$B$4:$B$114,$A17) | C17: =SUMIFS('Master BOM'!$M$4:$M$114,'Master BOM'!$B$4:$B$114,$A17) | D17: =SUMIFS('Master BOM'!$N$4:$N$114,'Master BOM'!$B$4:$B$114,$A17) | E17: =COUNTIFS('Master BOM'!$B$4:$B$114,$A17)
A18: Sim — Ethan | B18: =SUMIFS('Master BOM'!$L$4:$L$114,'Master BOM'!$B$4:$B$114,$A18) | C18: =SUMIFS('Master BOM'!$M$4:$M$114,'Master BOM'!$B$4:$B$114,$A18) | D18: =SUMIFS('Master BOM'!$N$4:$N$114,'Master BOM'!$B$4:$B$114,$A18) | E18: =COUNTIFS('Master BOM'!$B$4:$B$114,$A18)
A19: Web — Geet | B19: =SUMIFS('Master BOM'!$L$4:$L$114,'Master BOM'!$B$4:$B$114,$A19) | C19: =SUMIFS('Master BOM'!$M$4:$M$114,'Master BOM'!$B$4:$B$114,$A19) | D19: =SUMIFS('Master BOM'!$N$4:$N$114,'Master BOM'!$B$4:$B$114,$A19) | E19: =COUNTIFS('Master BOM'!$B$4:$B$114,$A19)
A20: TOTAL (USD) | B20: =SUM(B10:B19) | C20: =SUM(C10:C19) | D20: =SUM(D10:D19) | E20: =SUM(E10:E19)
A21: TOTAL LANDED (CAD, incl. duty/brokerage) | B21: =B20*$B$5*(1+$B$6) | C21: =C20*$B$5*(1+$B$6) | D21: =D20*$B$5*(1+$B$6)
A22: Cross-check vs Master BOM total | B22: =SUM('Master BOM'!$L$4:$L$114) | C22: =SUM('Master BOM'!$M$4:$M$114) | D22: =SUM('Master BOM'!$N$4:$N$114)
A25: SPEND BY CATEGORY (USD)
A26: Category | B26: Tier 1 — Shoestring | C26: Tier 2 — Moderate | D26: Tier 3 — Well-funded | E26: Line items
A27: Actuation / Mounting | B27: =SUMIFS('Master BOM'!$L$4:$L$114,'Master BOM'!$C$4:$C$114,$A27) | C27: =SUMIFS('Master BOM'!$M$4:$M$114,'Master BOM'!$C$4:$C$114,$A27) | D27: =SUMIFS('Master BOM'!$N$4:$N$114,'Master BOM'!$C$4:$C$114,$A27) | E27: =COUNTIFS('Master BOM'!$C$4:$C$114,$A27)
A28: Actuation — Brake / EBS | B28: =SUMIFS('Master BOM'!$L$4:$L$114,'Master BOM'!$C$4:$C$114,$A28) | C28: =SUMIFS('Master BOM'!$M$4:$M$114,'Master BOM'!$C$4:$C$114,$A28) | D28: =SUMIFS('Master BOM'!$N$4:$N$114,'Master BOM'!$C$4:$C$114,$A28) | E28: =COUNTIFS('Master BOM'!$C$4:$C$114,$A28)
A29: Actuation — Steering | B29: =SUMIFS('Master BOM'!$L$4:$L$114,'Master BOM'!$C$4:$C$114,$A29) | C29: =SUMIFS('Master BOM'!$M$4:$M$114,'Master BOM'!$C$4:$C$114,$A29) | D29: =SUMIFS('Master BOM'!$N$4:$N$114,'Master BOM'!$C$4:$C$114,$A29) | E29: =COUNTIFS('Master BOM'!$C$4:$C$114,$A29)
A30: Compute | B30: =SUMIFS('Master BOM'!$L$4:$L$114,'Master BOM'!$C$4:$C$114,$A30) | C30: =SUMIFS('Master BOM'!$M$4:$M$114,'Master BOM'!$C$4:$C$114,$A30) | D30: =SUMIFS('Master BOM'!$N$4:$N$114,'Master BOM'!$C$4:$C$114,$A30) | E30: =COUNTIFS('Master BOM'!$C$4:$C$114,$A30)
A31: Data / Storage | B31: =SUMIFS('Master BOM'!$L$4:$L$114,'Master BOM'!$C$4:$C$114,$A31) | C31: =SUMIFS('Master BOM'!$M$4:$M$114,'Master BOM'!$C$4:$C$114,$A31) | D31: =SUMIFS('Master BOM'!$N$4:$N$114,'Master BOM'!$C$4:$C$114,$A31) | E31: =COUNTIFS('Master BOM'!$C$4:$C$114,$A31)
A32: Facilities / Admin | B32: =SUMIFS('Master BOM'!$L$4:$L$114,'Master BOM'!$C$4:$C$114,$A32) | C32: =SUMIFS('Master BOM'!$M$4:$M$114,'Master BOM'!$C$4:$C$114,$A32) | D32: =SUMIFS('Master BOM'!$N$4:$N$114,'Master BOM'!$C$4:$C$114,$A32) | E32: =COUNTIFS('Master BOM'!$C$4:$C$114,$A32)
A33: Networking / Power | B33: =SUMIFS('Master BOM'!$L$4:$L$114,'Master BOM'!$C$4:$C$114,$A33) | C33: =SUMIFS('Master BOM'!$M$4:$M$114,'Master BOM'!$C$4:$C$114,$A33) | D33: =SUMIFS('Master BOM'!$N$4:$N$114,'Master BOM'!$C$4:$C$114,$A33) | E33: =COUNTIFS('Master BOM'!$C$4:$C$114,$A33)
A34: Safety / Rules Hardware | B34: =SUMIFS('Master BOM'!$L$4:$L$114,'Master BOM'!$C$4:$C$114,$A34) | C34: =SUMIFS('Master BOM'!$M$4:$M$114,'Master BOM'!$C$4:$C$114,$A34) | D34: =SUMIFS('Master BOM'!$N$4:$N$114,'Master BOM'!$C$4:$C$114,$A34) | E34: =COUNTIFS('Master BOM'!$C$4:$C$114,$A34)
A35: Safety Equipment | B35: =SUMIFS('Master BOM'!$L$4:$L$114,'Master BOM'!$C$4:$C$114,$A35) | C35: =SUMIFS('Master BOM'!$M$4:$M$114,'Master BOM'!$C$4:$C$114,$A35) | D35: =SUMIFS('Master BOM'!$N$4:$N$114,'Master BOM'!$C$4:$C$114,$A35) | E35: =COUNTIFS('Master BOM'!$C$4:$C$114,$A35)
A36: Sensing — Camera | B36: =SUMIFS('Master BOM'!$L$4:$L$114,'Master BOM'!$C$4:$C$114,$A36) | C36: =SUMIFS('Master BOM'!$M$4:$M$114,'Master BOM'!$C$4:$C$114,$A36) | D36: =SUMIFS('Master BOM'!$N$4:$N$114,'Master BOM'!$C$4:$C$114,$A36) | E36: =COUNTIFS('Master BOM'!$C$4:$C$114,$A36)
A37: Sensing — GNSS/INS | B37: =SUMIFS('Master BOM'!$L$4:$L$114,'Master BOM'!$C$4:$C$114,$A37) | C37: =SUMIFS('Master BOM'!$M$4:$M$114,'Master BOM'!$C$4:$C$114,$A37) | D37: =SUMIFS('Master BOM'!$N$4:$N$114,'Master BOM'!$C$4:$C$114,$A37) | E37: =COUNTIFS('Master BOM'!$C$4:$C$114,$A37)
A38: Sensing — LiDAR | B38: =SUMIFS('Master BOM'!$L$4:$L$114,'Master BOM'!$C$4:$C$114,$A38) | C38: =SUMIFS('Master BOM'!$M$4:$M$114,'Master BOM'!$C$4:$C$114,$A38) | D38: =SUMIFS('Master BOM'!$N$4:$N$114,'Master BOM'!$C$4:$C$114,$A38) | E38: =COUNTIFS('Master BOM'!$C$4:$C$114,$A38)
... A45: Web / Comms | B45: =SUMIFS('Master BOM'!$L$4:$L$114,'Master BOM'!$C$4:$C$114,$A45) | C45: =SUMIFS('Master BOM'!$M$4:$M$114,'Master BOM'!$C$4:$C$114,$A45) | D45: =SUMIFS('Master BOM'!$N$4:$N$114,'Master BOM'!$C$4:$C$114,$A45) | E45: =COUNTIFS('Master BOM'!$C$4:$C$114,$A45)
A46: TOTAL (USD) | B46: =SUM(B27:B45) | C46: =SUM(C27:C45) | D46: =SUM(D27:D45)
A49: RULES-CRITICAL SPEND ONLY (items marked Critical)
A50: Priority | B50: Tier 1 — Shoestring | C50: Tier 2 — Moderate | D50: Tier 3 — Well-funded | E50: Line items
A51: Critical | B51: =SUMIFS('Master BOM'!$L$4:$L$114,'Master BOM'!$O$4:$O$114,$A51) | C51: =SUMIFS('Master BOM'!$M$4:$M$114,'Master BOM'!$O$4:$O$114,$A51) | D51: =SUMIFS('Master BOM'!$N$4:$N$114,'Master BOM'!$O$4:$O$114,$A51) | E51: =COUNTIFS('Master BOM'!$O$4:$O$114,$A51)
A52: High | B52: =SUMIFS('Master BOM'!$L$4:$L$114,'Master BOM'!$O$4:$O$114,$A52) | C52: =SUMIFS('Master BOM'!$M$4:$M$114,'Master BOM'!$O$4:$O$114,$A52) | D52: =SUMIFS('Master BOM'!$N$4:$N$114,'Master BOM'!$O$4:$O$114,$A52) | E52: =COUNTIFS('Master BOM'!$O$4:$O$114,$A52)
...

Sheet DSO (Caleb)
A1: DSO — Caleb
A2: Responsibilities: Vehicle architecture, integration, safety & rules compliance, DV document submission
A3: All values pull live from 'Master BOM'. Edit costs there, not here.
A5: ID | B5: Category | C5: Item / Purpose | D5: Recommended Model / Spec | E5: Qty | F5: Unit Cost (USD) | G5: Tier 1 ($) | H5: Tier 2 ($) | I5: Tier 3 ($) | J5: Priority | K5: Lead Time | L5: Sponsorable? | M5: Rules Ref | N5: Notes / Rationale
A6: ='Master BOM'!A4 | B6: ='Master BOM'!C4 | C6: ='Master BOM'!D4 | D6: ='Master BOM'!E4 | E6: ='Master BOM'!F4 | F6: ='Master BOM'!G4 | G6: ='Master BOM'!L4 | H6: ='Master BOM'!M4 | I6: ='Master BOM'!N4 | J6: ='Master BOM'!O4 | K6: ='Master BOM'!P4 | L6: ='Master BOM'!Q4 | M6: ='Master BOM'!R4 | N6: ='Master BOM'!S4
A7: ='Master BOM'!A5 | B7: ='Master BOM'!C5 | C7: ='Master BOM'!D5 | D7: ='Master BOM'!E5 | E7: ='Master BOM'!F5 | F7: ='Master BOM'!G5 | G7: ='Master BOM'!L5 | H7: ='Master BOM'!M5 | I7: ='Master BOM'!N5 | J7: ='Master BOM'!O5 | K7: ='Master BOM'!P5 | L7: ='Master BOM'!Q5 | M7: ='Master BOM'!R5 | N7: ='Master BOM'!S5
A8: ='Master BOM'!A6 | B8: ='Master BOM'!C6 | C8: ='Master BOM'!D6 | D8: ='Master BOM'!E6 | E8: ='Master BOM'!F6 | F8: ='Master BOM'!G6 | G8: ='Master BOM'!L6 | H8: ='Master BOM'!M6 | I8: ='Master BOM'!N6 | J8: ='Master BOM'!O6 | K8: ='Master BOM'!P6 | L8: ='Master BOM'!Q6 | M8: ='Master BOM'!R6 | N8: ='Master BOM'!S6
A9: ='Master BOM'!A7 | B9: ='Master BOM'!C7 | C9: ='Master BOM'!D7 | D9: ='Master BOM'!E7 | E9: ='Master BOM'!F7 | F9: ='Master BOM'!G7 | G9: ='Master BOM'!L7 | H9: ='Master BOM'!M7 | I9: ='Master BOM'!N7 | J9: ='Master BOM'!O7 | K9: ='Master BOM'!P7 | L9: ='Master BOM'!Q7 | M9: ='Master BOM'!R7 | N9: ='Master BOM'!S7
A10: ='Master BOM'!A8 | B10: ='Master BOM'!C8 | C10: ='Master BOM'!D8 | D10: ='Master BOM'!E8 | E10: ='Master BOM'!F8 | F10: ='Master BOM'!G8 | G10: ='Master BOM'!L8 | H10: ='Master BOM'!M8 | I10: ='Master BOM'!N8 | J10: ='Master BOM'!O8 | K10: ='Master BOM'!P8 | L10: ='Master BOM'!Q8 | M10: ='Master BOM'!R8 | N10: ='Master BOM'!S8
A11: ='Master BOM'!A9 | B11: ='Master BOM'!C9 | C11: ='Master BOM'!D9 | D11: ='Master BOM'!E9 | E11: ='Master BOM'!F9 | F11: ='Master BOM'!G9 | G11: ='Master BOM'!L9 | H11: ='Master BOM'!M9 | I11: ='Master BOM'!N9 | J11: ='Master BOM'!O9 | K11: ='Master BOM'!P9 | L11: ='Master BOM'!Q9 | M11: ='Master BOM'!R9 | N11: ='Master BOM'!S9
A12: ='Master BOM'!A10 | B12: ='Master BOM'!C10 | C12: ='Master BOM'!D10 | D12: ='Master BOM'!E10 | E12: ='Master BOM'!F10 | F12: ='Master BOM'!G10 | G12: ='Master BOM'!L10 | H12: ='Master BOM'!M10 | I12: ='Master BOM'!N10 | J12: ='Master BOM'!O10 | K12: ='Master BOM'!P10 | L12: ='Master BOM'!Q10 | M12: ='Master BOM'!R10 | N12: ='Master BOM'!S10
A13: ='Master BOM'!A11 | B13: ='Master BOM'!C11 | C13: ='Master BOM'!D11 | D13: ='Master BOM'!E11 | E13: ='Master BOM'!F11 | F13: ='Master BOM'!G11 | G13: ='Master BOM'!L11 | H13: ='Master BOM'!M11 | I13: ='Master BOM'!N11 | J13: ='Master BOM'!O11 | K13: ='Master BOM'!P11 | L13: ='Master BOM'!Q11 | M13: ='Master BOM'!R11 | N13: ='Master BOM'!S11
A14: ='Master BOM'!A12 | B14: ='Master BOM'!C12 | C14: ='Master BOM'!D12 | D14: ='Master BOM'!E12 | E14: ='Master BOM'!F12 | F14: ='Master BOM'!G12 | G14: ='Master BOM'!L12 | H14: ='Master BOM'!M12 | I14: ='Master BOM'!N12 | J14: ='Master BOM'!O12 | K14: ='Master BOM'!P12 | L14: ='Master BOM'!Q12 | M14: ='Master BOM'!R12 | N14: ='Master BOM'!S12
A15: ='Master BOM'!A13 | B15: ='Master BOM'!C13 | C15: ='Master BOM'!D13 | D15: ='Master BOM'!E13 | E15: ='Master BOM'!F13 | F15: ='Master BOM'!G13 | G15: ='Master BOM'!L13 | H15: ='Master BOM'!M13 | I15: ='Master BOM'!N13 | J15: ='Master BOM'!O13 | K15: ='Master BOM'!P13 | L15: ='Master BOM'!Q13 | M15: ='Master BOM'!R13 | N15: ='Master BOM'!S13
C17: ROLE TOTAL | G17: =SUM(G6:G15) | H17: =SUM(H6:H15) | I17: =SUM(I6:I15)
C19: Tier columns are alternative configurations, not cumulative. Pick the tier your funding supports.

Sheet Team-Wide (Everyone)
A1: Team-Wide — Everyone
A2: Responsibilities: Competition strategy, team constraints, design goals, safety concepts, version control
A3: All values pull live from 'Master BOM'. Edit costs there, not here.
A5: ID | B5: Category | C5: Item / Purpose | D5: Recommended Model / Spec | E5: Qty | F5: Unit Cost (USD) | G5: Tier 1 ($) | H5: Tier 2 ($) | I5: Tier 3 ($) | J5: Priority | K5: Lead Time | L5: Sponsorable? | M5: Rules Ref | N5: Notes / Rationale
A6: ='Master BOM'!A14 | B6: ='Master BOM'!C14 | C6: ='Master BOM'!D14 | D6: ='Master BOM'!E14 | E6: ='Master BOM'!F14 | F6: ='Master BOM'!G14 | G6: ='Master BOM'!L14 | H6: ='Master BOM'!M14 | I6: ='Master BOM'!N14 | J6: ='Master BOM'!O14 | K6: ='Master BOM'!P14 | L6: ='Master BOM'!Q14 | M6: ='Master BOM'!R14 | N6: ='Master BOM'!S14
A7: ='Master BOM'!A15 | B7: ='Master BOM'!C15 | C7: ='Master BOM'!D15 | D7: ='Master BOM'!E15 | E7: ='Master BOM'!F15 | F7: ='Master BOM'!G15 | G7: ='Master BOM'!L15 | H7: ='Master BOM'!M15 | I7: ='Master BOM'!N15 | J7: ='Master BOM'!O15 | K7: ='Master BOM'!P15 | L7: ='Master BOM'!Q15 | M7: ='Master BOM'!R15 | N7: ='Master BOM'!S15
A8: ='Master BOM'!A16 | B8: ='Master BOM'!C16 | C8: ='Master BOM'!D16 | D8: ='Master BOM'!E16 | E8: ='Master BOM'!F16 | F8: ='Master BOM'!G16 | G8: ='Master BOM'!L16 | H8: ='Master BOM'!M16 | I8: ='Master BOM'!N16 | J8: ='Master BOM'!O16 | K8: ='Master BOM'!P16 | L8: ='Master BOM'!Q16 | M8: ='Master BOM'!R16 | N8: ='Master BOM'!S16
A9: ='Master BOM'!A17 | B9: ='Master BOM'!C17 | C9: ='Master BOM'!D17 | D9: ='Master BOM'!E17 | E9: ='Master BOM'!F17 | F9: ='Master BOM'!G17 | G9: ='Master BOM'!L17 | H9: ='Master BOM'!M17 | I9: ='Master BOM'!N17 | J9: ='Master BOM'!O17 | K9: ='Master BOM'!P17 | L9: ='Master BOM'!Q17 | M9: ='Master BOM'!R17 | N9: ='Master BOM'!S17
C11: ROLE TOTAL | G11: =SUM(G6:G9) | H11: =SUM(H6:H9) | I11: =SUM(I6:I9)
C13: Tier columns are alternative configurations, not cumulative. Pick the tier your funding supports.

Sheet Perception (Amanuel-Irvine)
A1: Perception — Amanuel + Irvine + Caleb
A2: Responsibilities: Sensor placement/coverage, cone detection, low-level & object-level fusion, pipeline latency, GT validation
A3: All values pull live from 'Master BOM'. Edit costs there, not here.
A5: ID | B5: Category | C5: Item / Purpose | D5: Recommended Model / Spec | E5: Qty | F5: Unit Cost (USD) | G5: Tier 1 ($) | H5: Tier 2 ($) | I5: Tier 3 ($) | J5: Priority | K5: Lead Time | L5: Sponsorable? | M5: Rules Ref | N5: Notes / Rationale
A6: ='Master BOM'!A18 | B6: ='Master BOM'!C18 | C6: ='Master BOM'!D18 | D6: ='Master BOM'!E18 | E6: ='Master BOM'!F18 | F6: ='Master BOM'!G18 | G6: ='Master BOM'!L18 | H6: ='Master BOM'!M18 | I6: ='Master BOM'!N18 | J6: ='Master BOM'!O18 | K6: ='Master BOM'!P18 | L6: ='Master BOM'!Q18 | M6: ='Master BOM'!R18 | N6: ='Master BOM'!S18
A7: ='Master BOM'!A19 | B7: ='Master BOM'!C19 | C7: ='Master BOM'!D19 | D7: ='Master BOM'!E19 | E7: ='Master BOM'!F19 | F7: ='Master BOM'!G19 | G7: ='Master BOM'!L19 | H7: ='Master BOM'!M19 | I7: ='Master BOM'!N19 | J7: ='Master BOM'!O19 | K7: ='Master BOM'!P19 | L7: ='Master BOM'!Q19 | M7: ='Master BOM'!R19 | N7: ='Master BOM'!S19
A8: ='Master BOM'!A20 | B8: ='Master BOM'!C20 | C8: ='Master BOM'!D20 | D8: ='Master BOM'!E20 | E8: ='Master BOM'!F20 | F8: ='Master BOM'!G20 | G8: ='Master BOM'!L20 | H8: ='Master BOM'!M20 | I8: ='Master BOM'!N20 | J8: ='Master BOM'!O20 | K8: ='Master BOM'!P20 | L8: ='Master BOM'!Q20 | M8: ='Master BOM'!R20 | N8: ='Master BOM'!S20
A9: ='Master BOM'!A21 | B9: ='Master BOM'!C21 | C9: ='Master BOM'!D21 | D9: ='Master BOM'!E21 | E9: ='Master BOM'!F21 | F9: ='Master BOM'!G21 | G9: ='Master BOM'!L21 | H9: ='Master BOM'!M21 | I9: ='Master BOM'!N21 | J9: ='Master BOM'!O21 | K9: ='Master BOM'!P21 | L9: ='Master BOM'!Q21 | M9: ='Master BOM'!R21 | N9: ='Master BOM'!S21
A10: ='Master BOM'!A22 | B10: ='Master BOM'!C22 | C10: ='Master BOM'!D22 | D10: ='Master BOM'!E22 | E10: ='Master BOM'!F22 | F10: ='Master BOM'!G22 | G10: ='Master BOM'!L22 | H10: ='Master BOM'!M22 | I10: ='Master BOM'!N22 | J10: ='Master BOM'!O22 | K10: ='Master BOM'!P22 | L10: ='Master BOM'!Q22 | M10: ='Master BOM'!R22 | N10: ='Master BOM'!S22
A11: ='Master BOM'!A23 | B11: ='Master BOM'!C23 | C11: ='Master BOM'!D23 | D11: ='Master BOM'!E23 | E11: ='Master BOM'!F23 | F11: ='Master BOM'!G23 | G11: ='Master BOM'!L23 | H11: ='Master BOM'!M23 | I11: ='Master BOM'!N23 | J11: ='Master BOM'!O23 | K11: ='Master BOM'!P23 | L11: ='Master BOM'!Q23 | M11: ='Master BOM'!R23 | N11: ='Master BOM'!S23
A12: ='Master BOM'!A24 | B12: ='Master BOM'!C24 | C12: ='Master BOM'!D24 | D12: ='Master BOM'!E24 | E12: ='Master BOM'!F24 | F12: ='Master BOM'!G24 | G12: ='Master BOM'!L24 | H12: ='Master BOM'!M24 | I12: ='Master BOM'!N24 | J12: ='Master BOM'!O24 | K12: ='Master BOM'!P24 | L12: ='Master BOM'!Q24 | M12: ='Master BOM'!R24 | N12: ='Master BOM'!S24
A13: ='Master BOM'!A25 | B13: ='Master BOM'!C25 | C13: ='Master BOM'!D25 | D13: ='Master BOM'!E25 | E13: ='Master BOM'!F25 | F13: ='Master BOM'!G25 | G13: ='Master BOM'!L25 | H13: ='Master BOM'!M25 | I13: ='Master BOM'!N25 | J13: ='Master BOM'!O25 | K13: ='Master BOM'!P25 | L13: ='Master BOM'!Q25 | M13: ='Master BOM'!R25 | N13: ='Master BOM'!S25
A14: ='Master BOM'!A26 | B14: ='Master BOM'!C26 | C14: ='Master BOM'!D26 | D14: ='Master BOM'!E26 | E14: ='Master BOM'!F26 | F14: ='Master BOM'!G26 | G14: ='Master BOM'!L26 | H14: ='Master BOM'!M26 | I14: ='Master BOM'!N26 | J14: ='Master BOM'!O26 | K14: ='Master BOM'!P26 | L14: ='Master BOM'!Q26 | M14: ='Master BOM'!R26 | N14: ='Master BOM'!S26
A15: ='Master BOM'!A27 | B15: ='Master BOM'!C27 | C15: ='Master BOM'!D27 | D15: ='Master BOM'!E27 | E15: ='Master BOM'!F27 | F15: ='Master BOM'!G27 | G15: ='Master BOM'!L27 | H15: ='Master BOM'!M27 | I15: ='Master BOM'!N27 | J15: ='Master BOM'!O27 | K15: ='Master BOM'!P27 | L15: ='Master BOM'!Q27 | M15: ='Master BOM'!R27 | N15: ='Master BOM'!S27
A16: ='Master BOM'!A28 | B16: ='Master BOM'!C28 | C16: ='Master BOM'!D28 | D16: ='Master BOM'!E28 | E16: ='Master BOM'!F28 | F16: ='Master BOM'!G28 | G16: ='Master BOM'!L28 | H16: ='Master BOM'!M28 | I16: ='Master BOM'!N28 | J16: ='Master BOM'!O28 | K16: ='Master BOM'!P28 | L16: ='Master BOM'!Q28 | M16: ='Master BOM'!R28 | N16: ='Master BOM'!S28
A17: ='Master BOM'!A29 | B17: ='Master BOM'!C29 | C17: ='Master BOM'!D29 | D17: ='Master BOM'!E29 | E17: ='Master BOM'!F29 | F17: ='Master BOM'!G29 | G17: ='Master BOM'!L29 | H17: ='Master BOM'!M29 | I17: ='Master BOM'!N29 | J17: ='Master BOM'!O29 | K17: ='Master BOM'!P29 | L17: ='Master BOM'!Q29 | M17: ='Master BOM'!R29 | N17: ='Master BOM'!S29
... A20: ='Master BOM'!A32 | B20: ='Master BOM'!C32 | C20: ='Master BOM'!D32 | D20: ='Master BOM'!E32 | E20: ='Master BOM'!F32 | F20: ='Master BOM'!G32 | G20: ='Master BOM'!L32 | H20: ='Master BOM'!M32 | I20: ='Master BOM'!N32 | J20: ='Master BOM'!O32 | K20: ='Master BOM'!P32 | L20: ='Master BOM'!Q32 | M20: ='Master BOM'!R32 | N20: ='Master BOM'!S32
C22: ROLE TOTAL | G22: =SUM(G6:G20) | H22: =SUM(H6:H20) | I22: =SUM(I6:I20)
C24: Tier columns are alternative configurations, not cumulative. Pick the tier your funding supports.

Sheet Mapping (Angel)
A1: Mapping — Angel
A2: Responsibilities: Localization concept, map representation, vehicle state estimation, filter selection, loop closure, localization accuracy
A3: All values pull live from 'Master BOM'. Edit costs there, not here.
A5: ID | B5: Category | C5: Item / Purpose | D5: Recommended Model / Spec | E5: Qty | F5: Unit Cost (USD) | G5: Tier 1 ($) | H5: Tier 2 ($) | I5: Tier 3 ($) | J5: Priority | K5: Lead Time | L5: Sponsorable? | M5: Rules Ref | N5: Notes / Rationale
A6: ='Master BOM'!A33 | B6: ='Master BOM'!C33 | C6: ='Master BOM'!D33 | D6: ='Master BOM'!E33 | E6: ='Master BOM'!F33 | F6: ='Master BOM'!G33 | G6: ='Master BOM'!L33 | H6: ='Master BOM'!M33 | I6: ='Master BOM'!N33 | J6: ='Master BOM'!O33 | K6: ='Master BOM'!P33 | L6: ='Master BOM'!Q33 | M6: ='Master BOM'!R33 | N6: ='Master BOM'!S33
A7: ='Master BOM'!A34 | B7: ='Master BOM'!C34 | C7: ='Master BOM'!D34 | D7: ='Master BOM'!E34 | E7: ='Master BOM'!F34 | F7: ='Master BOM'!G34 | G7: ='Master BOM'!L34 | H7: ='Master BOM'!M34 | I7: ='Master BOM'!N34 | J7: ='Master BOM'!O34 | K7: ='Master BOM'!P34 | L7: ='Master BOM'!Q34 | M7: ='Master BOM'!R34 | N7: ='Master BOM'!S34
A8: ='Master BOM'!A35 | B8: ='Master BOM'!C35 | C8: ='Master BOM'!D35 | D8: ='Master BOM'!E35 | E8: ='Master BOM'!F35 | F8: ='Master BOM'!G35 | G8: ='Master BOM'!L35 | H8: ='Master BOM'!M35 | I8: ='Master BOM'!N35 | J8: ='Master BOM'!O35 | K8: ='Master BOM'!P35 | L8: ='Master BOM'!Q35 | M8: ='Master BOM'!R35 | N8: ='Master BOM'!S35
A9: ='Master BOM'!A36 | B9: ='Master BOM'!C36 | C9: ='Master BOM'!D36 | D9: ='Master BOM'!E36 | E9: ='Master BOM'!F36 | F9: ='Master BOM'!G36 | G9: ='Master BOM'!L36 | H9: ='Master BOM'!M36 | I9: ='Master BOM'!N36 | J9: ='Master BOM'!O36 | K9: ='Master BOM'!P36 | L9: ='Master BOM'!Q36 | M9: ='Master BOM'!R36 | N9: ='Master BOM'!S36
A10: ='Master BOM'!A37 | B10: ='Master BOM'!C37 | C10: ='Master BOM'!D37 | D10: ='Master BOM'!E37 | E10: ='Master BOM'!F37 | F10: ='Master BOM'!G37 | G10: ='Master BOM'!L37 | H10: ='Master BOM'!M37 | I10: ='Master BOM'!N37 | J10: ='Master BOM'!O37 | K10: ='Master BOM'!P37 | L10: ='Master BOM'!Q37 | M10: ='Master BOM'!R37 | N10: ='Master BOM'!S37
A11: ='Master BOM'!A38 | B11: ='Master BOM'!C38 | C11: ='Master BOM'!D38 | D11: ='Master BOM'!E38 | E11: ='Master BOM'!F38 | F11: ='Master BOM'!G38 | G11: ='Master BOM'!L38 | H11: ='Master BOM'!M38 | I11: ='Master BOM'!N38 | J11: ='Master BOM'!O38 | K11: ='Master BOM'!P38 | L11: ='Master BOM'!Q38 | M11: ='Master BOM'!R38 | N11: ='Master BOM'!S38
A12: ='Master BOM'!A39 | B12: ='Master BOM'!C39 | C12: ='Master BOM'!D39 | D12: ='Master BOM'!E39 | E12: ='Master BOM'!F39 | F12: ='Master BOM'!G39 | G12: ='Master BOM'!L39 | H12: ='Master BOM'!M39 | I12: ='Master BOM'!N39 | J12: ='Master BOM'!O39 | K12: ='Master BOM'!P39 | L12: ='Master BOM'!Q39 | M12: ='Master BOM'!R39 | N12: ='Master BOM'!S39
A13: ='Master BOM'!A40 | B13: ='Master BOM'!C40 | C13: ='Master BOM'!D40 | D13: ='Master BOM'!E40 | E13: ='Master BOM'!F40 | F13: ='Master BOM'!G40 | G13: ='Master BOM'!L40 | H13: ='Master BOM'!M40 | I13: ='Master BOM'!N40 | J13: ='Master BOM'!O40 | K13: ='Master BOM'!P40 | L13: ='Master BOM'!Q40 | M13: ='Master BOM'!R40 | N13: ='Master BOM'!S40
C15: ROLE TOTAL | G15: =SUM(G6:G13) | H15: =SUM(H6:H13) | I15: =SUM(I6:I13)
C17: Tier columns are alternative configurations, not cumulative. Pick the tier your funding supports.

Sheet Planning (Ced)
A1: Planning — Ced
A2: Responsibilities: Planning concept, path generation, vehicle model, speed profile, lateral/longitudinal control, actuator interfaces, control validation
A3: All values pull live from 'Master BOM'. Edit costs there, not here.
A5: ID | B5: Category | C5: Item / Purpose | D5: Recommended Model / Spec | E5: Qty | F5: Unit Cost (USD) | G5: Tier 1 ($) | H5: Tier 2 ($) | I5: Tier 3 ($) | J5: Priority | K5: Lead Time | L5: Sponsorable? | M5: Rules Ref | N5: Notes / Rationale
A6: ='Master BOM'!A41 | B6: ='Master BOM'!C41 | C6: ='Master BOM'!D41 | D6: ='Master BOM'!E41 | E6: ='Master BOM'!F41 | F6: ='Master BOM'!G41 | G6: ='Master BOM'!L41 | H6: ='Master BOM'!M41 | I6: ='Master BOM'!N41 | J6: ='Master BOM'!O41 | K6: ='Master BOM'!P41 | L6: ='Master BOM'!Q41 | M6: ='Master BOM'!R41 | N6: ='Master BOM'!S41
A7: ='Master BOM'!A42 | B7: ='Master BOM'!C42 | C7: ='Master BOM'!D42 | D7: ='Master BOM'!E42 | E7: ='Master BOM'!F42 | F7: ='Master BOM'!G42 | G7: ='Master BOM'!L42 | H7: ='Master BOM'!M42 | I7: ='Master BOM'!N42 | J7: ='Master BOM'!O42 | K7: ='Master BOM'!P42 | L7: ='Master BOM'!Q42 | M7: ='Master BOM'!R42 | N7: ='Master BOM'!S42
A8: ='Master BOM'!A43 | B8: ='Master BOM'!C43 | C8: ='Master BOM'!D43 | D8: ='Master BOM'!E43 | E8: ='Master BOM'!F43 | F8: ='Master BOM'!G43 | G8: ='Master BOM'!L43 | H8: ='Master BOM'!M43 | I8: ='Master BOM'!N43 | J8: ='Master BOM'!O43 | K8: ='Master BOM'!P43 | L8: ='Master BOM'!Q43 | M8: ='Master BOM'!R43 | N8: ='Master BOM'!S43
A9: ='Master BOM'!A44 | B9: ='Master BOM'!C44 | C9: ='Master BOM'!D44 | D9: ='Master BOM'!E44 | E9: ='Master BOM'!F44 | F9: ='Master BOM'!G44 | G9: ='Master BOM'!L44 | H9: ='Master BOM'!M44 | I9: ='Master BOM'!N44 | J9: ='Master BOM'!O44 | K9: ='Master BOM'!P44 | L9: ='Master BOM'!Q44 | M9: ='Master BOM'!R44 | N9: ='Master BOM'!S44
A10: ='Master BOM'!A45 | B10: ='Master BOM'!C45 | C10: ='Master BOM'!D45 | D10: ='Master BOM'!E45 | E10: ='Master BOM'!F45 | F10: ='Master BOM'!G45 | G10: ='Master BOM'!L45 | H10: ='Master BOM'!M45 | I10: ='Master BOM'!N45 | J10: ='Master BOM'!O45 | K10: ='Master BOM'!P45 | L10: ='Master BOM'!Q45 | M10: ='Master BOM'!R45 | N10: ='Master BOM'!S45
C12: ROLE TOTAL | G12: =SUM(G6:G10) | H12: =SUM(H6:H10) | I12: =SUM(I6:I10)
C14: Tier columns are alternative configurations, not cumulative. Pick the tier your funding supports.

Sheet Firmware (Mason)
A1: Firmware — Mason
A2: Responsibilities: Bring-up of LiDAR/camera/Jetson, low-level comms (CAN/UART/SPI/ADC), state machine, VCU, actuation motors, DMI dash, Docker
A3: All values pull live from 'Master BOM'. Edit costs there, not here.
A5: ID | B5: Category | C5: Item / Purpose | D5: Recommended Model / Spec | E5: Qty | F5: Unit Cost (USD) | G5: Tier 1 ($) | H5: Tier 2 ($) | I5: Tier 3 ($) | J5: Priority | K5: Lead Time | L5: Sponsorable? | M5: Rules Ref | N5: Notes / Rationale
A6: ='Master BOM'!A46 | B6: ='Master BOM'!C46 | C6: ='Master BOM'!D46 | D6: ='Master BOM'!E46 | E6: ='Master BOM'!F46 | F6: ='Master BOM'!G46 | G6: ='Master BOM'!L46 | H6: ='Master BOM'!M46 | I6: ='Master BOM'!N46 | J6: ='Master BOM'!O46 | K6: ='Master BOM'!P46 | L6: ='Master BOM'!Q46 | M6: ='Master BOM'!R46 | N6: ='Master BOM'!S46
A7: ='Master BOM'!A47 | B7: ='Master BOM'!C47 | C7: ='Master BOM'!D47 | D7: ='Master BOM'!E47 | E7: ='Master BOM'!F47 | F7: ='Master BOM'!G47 | G7: ='Master BOM'!L47 | H7: ='Master BOM'!M47 | I7: ='Master BOM'!N47 | J7: ='Master BOM'!O47 | K7: ='Master BOM'!P47 | L7: ='Master BOM'!Q47 | M7: ='Master BOM'!R47 | N7: ='Master BOM'!S47
A8: ='Master BOM'!A48 | B8: ='Master BOM'!C48 | C8: ='Master BOM'!D48 | D8: ='Master BOM'!E48 | E8: ='Master BOM'!F48 | F8: ='Master BOM'!G48 | G8: ='Master BOM'!L48 | H8: ='Master BOM'!M48 | I8: ='Master BOM'!N48 | J8: ='Master BOM'!O48 | K8: ='Master BOM'!P48 | L8: ='Master BOM'!Q48 | M8: ='Master BOM'!R48 | N8: ='Master BOM'!S48
A9: ='Master BOM'!A49 | B9: ='Master BOM'!C49 | C9: ='Master BOM'!D49 | D9: ='Master BOM'!E49 | E9: ='Master BOM'!F49 | F9: ='Master BOM'!G49 | G9: ='Master BOM'!L49 | H9: ='Master BOM'!M49 | I9: ='Master BOM'!N49 | J9: ='Master BOM'!O49 | K9: ='Master BOM'!P49 | L9: ='Master BOM'!Q49 | M9: ='Master BOM'!R49 | N9: ='Master BOM'!S49
A10: ='Master BOM'!A50 | B10: ='Master BOM'!C50 | C10: ='Master BOM'!D50 | D10: ='Master BOM'!E50 | E10: ='Master BOM'!F50 | F10: ='Master BOM'!G50 | G10: ='Master BOM'!L50 | H10: ='Master BOM'!M50 | I10: ='Master BOM'!N50 | J10: ='Master BOM'!O50 | K10: ='Master BOM'!P50 | L10: ='Master BOM'!Q50 | M10: ='Master BOM'!R50 | N10: ='Master BOM'!S50
A11: ='Master BOM'!A51 | B11: ='Master BOM'!C51 | C11: ='Master BOM'!D51 | D11: ='Master BOM'!E51 | E11: ='Master BOM'!F51 | F11: ='Master BOM'!G51 | G11: ='Master BOM'!L51 | H11: ='Master BOM'!M51 | I11: ='Master BOM'!N51 | J11: ='Master BOM'!O51 | K11: ='Master BOM'!P51 | L11: ='Master BOM'!Q51 | M11: ='Master BOM'!R51 | N11: ='Master BOM'!S51
A12: ='Master BOM'!A52 | B12: ='Master BOM'!C52 | C12: ='Master BOM'!D52 | D12: ='Master BOM'!E52 | E12: ='Master BOM'!F52 | F12: ='Master BOM'!G52 | G12: ='Master BOM'!L52 | H12: ='Master BOM'!M52 | I12: ='Master BOM'!N52 | J12: ='Master BOM'!O52 | K12: ='Master BOM'!P52 | L12: ='Master BOM'!Q52 | M12: ='Master BOM'!R52 | N12: ='Master BOM'!S52
A13: ='Master BOM'!A53 | B13: ='Master BOM'!C53 | C13: ='Master BOM'!D53 | D13: ='Master BOM'!E53 | E13: ='Master BOM'!F53 | F13: ='Master BOM'!G53 | G13: ='Master BOM'!L53 | H13: ='Master BOM'!M53 | I13: ='Master BOM'!N53 | J13: ='Master BOM'!O53 | K13: ='Master BOM'!P53 | L13: ='Master BOM'!Q53 | M13: ='Master BOM'!R53 | N13: ='Master BOM'!S53
A14: ='Master BOM'!A54 | B14: ='Master BOM'!C54 | C14: ='Master BOM'!D54 | D14: ='Master BOM'!E54 | E14: ='Master BOM'!F54 | F14: ='Master BOM'!G54 | G14: ='Master BOM'!L54 | H14: ='Master BOM'!M54 | I14: ='Master BOM'!N54 | J14: ='Master BOM'!O54 | K14: ='Master BOM'!P54 | L14: ='Master BOM'!Q54 | M14: ='Master BOM'!R54 | N14: ='Master BOM'!S54
A15: ='Master BOM'!A55 | B15: ='Master BOM'!C55 | C15: ='Master BOM'!D55 | D15: ='Master BOM'!E55 | E15: ='Master BOM'!F55 | F15: ='Master BOM'!G55 | G15: ='Master BOM'!L55 | H15: ='Master BOM'!M55 | I15: ='Master BOM'!N55 | J15: ='Master BOM'!O55 | K15: ='Master BOM'!P55 | L15: ='Master BOM'!Q55 | M15: ='Master BOM'!R55 | N15: ='Master BOM'!S55
A16: ='Master BOM'!A56 | B16: ='Master BOM'!C56 | C16: ='Master BOM'!D56 | D16: ='Master BOM'!E56 | E16: ='Master BOM'!F56 | F16: ='Master BOM'!G56 | G16: ='Master BOM'!L56 | H16: ='Master BOM'!M56 | I16: ='Master BOM'!N56 | J16: ='Master BOM'!O56 | K16: ='Master BOM'!P56 | L16: ='Master BOM'!Q56 | M16: ='Master BOM'!R56 | N16: ='Master BOM'!S56
A17: ='Master BOM'!A57 | B17: ='Master BOM'!C57 | C17: ='Master BOM'!D57 | D17: ='Master BOM'!E57 | E17: ='Master BOM'!F57 | F17: ='Master BOM'!G57 | G17: ='Master BOM'!L57 | H17: ='Master BOM'!M57 | I17: ='Master BOM'!N57 | J17: ='Master BOM'!O57 | K17: ='Master BOM'!P57 | L17: ='Master BOM'!Q57 | M17: ='Master BOM'!R57 | N17: ='Master BOM'!S57
... A28: ='Master BOM'!A68 | B28: ='Master BOM'!C68 | C28: ='Master BOM'!D68 | D28: ='Master BOM'!E68 | E28: ='Master BOM'!F68 | F28: ='Master BOM'!G68 | G28: ='Master BOM'!L68 | H28: ='Master BOM'!M68 | I28: ='Master BOM'!N68 | J28: ='Master BOM'!O68 | K28: ='Master BOM'!P68 | L28: ='Master BOM'!Q68 | M28: ='Master BOM'!R68 | N28: ='Master BOM'!S68
C30: ROLE TOTAL | G30: =SUM(G6:G28) | H30: =SUM(H6:H28) | I30: =SUM(I6:I28)
C32: Tier columns are alternative configurations, not cumulative. Pick the tier your funding supports.

Sheet Mech-EE (UNASSIGNED)
A1: Mech/EE Interface — UNASSIGNED (DSO coordinates)
A2: Responsibilities: Steering actuator + EBS hardware. No owner on the org chart — see README gap flag
A3: All values pull live from 'Master BOM'. Edit costs there, not here.
A4: OWNERSHIP GAP: no box on the org chart owns this work. DSO owns integration across mech and sparkies and has final say on safety and rules compliance, so these items sit here until a named owner exists. These are the two most common causes of failing DV technical inspection.
A6: ID | B6: Category | C6: Item / Purpose | D6: Recommended Model / Spec | E6: Qty | F6: Unit Cost (USD) | G6: Tier 1 ($) | H6: Tier 2 ($) | I6: Tier 3 ($) | J6: Priority | K6: Lead Time | L6: Sponsorable? | M6: Rules Ref | N6: Notes / Rationale
A7: ='Master BOM'!A69 | B7: ='Master BOM'!C69 | C7: ='Master BOM'!D69 | D7: ='Master BOM'!E69 | E7: ='Master BOM'!F69 | F7: ='Master BOM'!G69 | G7: ='Master BOM'!L69 | H7: ='Master BOM'!M69 | I7: ='Master BOM'!N69 | J7: ='Master BOM'!O69 | K7: ='Master BOM'!P69 | L7: ='Master BOM'!Q69 | M7: ='Master BOM'!R69 | N7: ='Master BOM'!S69
A8: ='Master BOM'!A70 | B8: ='Master BOM'!C70 | C8: ='Master BOM'!D70 | D8: ='Master BOM'!E70 | E8: ='Master BOM'!F70 | F8: ='Master BOM'!G70 | G8: ='Master BOM'!L70 | H8: ='Master BOM'!M70 | I8: ='Master BOM'!N70 | J8: ='Master BOM'!O70 | K8: ='Master BOM'!P70 | L8: ='Master BOM'!Q70 | M8: ='Master BOM'!R70 | N8: ='Master BOM'!S70
A9: ='Master BOM'!A71 | B9: ='Master BOM'!C71 | C9: ='Master BOM'!D71 | D9: ='Master BOM'!E71 | E9: ='Master BOM'!F71 | F9: ='Master BOM'!G71 | G9: ='Master BOM'!L71 | H9: ='Master BOM'!M71 | I9: ='Master BOM'!N71 | J9: ='Master BOM'!O71 | K9: ='Master BOM'!P71 | L9: ='Master BOM'!Q71 | M9: ='Master BOM'!R71 | N9: ='Master BOM'!S71
A10: ='Master BOM'!A72 | B10: ='Master BOM'!C72 | C10: ='Master BOM'!D72 | D10: ='Master BOM'!E72 | E10: ='Master BOM'!F72 | F10: ='Master BOM'!G72 | G10: ='Master BOM'!L72 | H10: ='Master BOM'!M72 | I10: ='Master BOM'!N72 | J10: ='Master BOM'!O72 | K10: ='Master BOM'!P72 | L10: ='Master BOM'!Q72 | M10: ='Master BOM'!R72 | N10: ='Master BOM'!S72
